✅ 参数加载成功： {'user_agent': 'Mozilla/5.0 (Windows NT 10.0; Win64; x64) AppleWebKit/537.36 (KHTML, like Gecko) Chrome/137.0.0.0 Safari/537.36', 'browser_major_version': '137', 'lang': {'browser': 'zh-CN,en-US,zh-HK', 'browser_interface': 'zh-CN', 'header': 'zh-CN,zh;q=0.9,en-US;q=0.8,en;q=0.7,zh-HK;q=0.6'}, 'timezone': 'Asia/Shanghai', 'ip': {'http': {'ip': '47.107.153.102', 'port': 12457, 'account': 'auto', 'password': 'NHbvbCw14H4kmOtd'}}, 'screen_size': {'width': 1920, 'height': 1080}}
Exception ignored in: <function _ProactorBasePipeTransport.__del__ at 0x000001FECD253670>
Traceback (most recent call last):
  File "c:\users\zhong\appdata\local\programs\python\python38\lib\asyncio\proactor_events.py", line 116, in __del__
    self.close()
  File "c:\users\zhong\appdata\local\programs\python\python38\lib\asyncio\proactor_events.py", line 108, in close
    self._loop.call_soon(self._call_connection_lost, None)
  File "c:\users\zhong\appdata\local\programs\python\python38\lib\asyncio\base_events.py", line 711, in call_soon
    self._check_closed()
  File "c:\users\zhong\appdata\local\programs\python\python38\lib\asyncio\base_events.py", line 504, in _check_closed
    raise RuntimeError('Event loop is closed')
RuntimeError: Event loop is closed
Exception ignored in: <function _ProactorBasePipeTransport.__del__ at 0x000001FECD253670>
Traceback (most recent call last):
  File "c:\users\zhong\appdata\local\programs\python\python38\lib\asyncio\proactor_events.py", line 116, in __del__
    self.close()
  File "c:\users\zhong\appdata\local\programs\python\python38\lib\asyncio\proactor_events.py", line 108, in close
    self._loop.call_soon(self._call_connection_lost, None)
  File "c:\users\zhong\appdata\local\programs\python\python38\lib\asyncio\base_events.py", line 711, in call_soon
    self._check_closed()
  File "c:\users\zhong\appdata\local\programs\python\python38\lib\asyncio\base_events.py", line 504, in _check_closed
    raise RuntimeError('Event loop is closed')
RuntimeError: Event loop is closed
Exception ignored in: <function _ProactorBasePipeTransport.__del__ at 0x000001FECD253670>
Traceback (most recent call last):
  File "c:\users\zhong\appdata\local\programs\python\python38\lib\asyncio\proactor_events.py", line 116, in __del__
    self.close()
  File "c:\users\zhong\appdata\local\programs\python\python38\lib\asyncio\proactor_events.py", line 108, in close
    self._loop.call_soon(self._call_connection_lost, None)
  File "c:\users\zhong\appdata\local\programs\python\python38\lib\asyncio\base_events.py", line 711, in call_soon
    self._check_closed()
  File "c:\users\zhong\appdata\local\programs\python\python38\lib\asyncio\base_events.py", line 504, in _check_closed
    raise RuntimeError('Event loop is closed')
RuntimeError: Event loop is closed
Exception ignored in: <function _ProactorBasePipeTransport.__del__ at 0x000001FECD253670>
Traceback (most recent call last):
  File "c:\users\zhong\appdata\local\programs\python\python38\lib\asyncio\proactor_events.py", line 116, in __del__
    self.close()
  File "c:\users\zhong\appdata\local\programs\python\python38\lib\asyncio\proactor_events.py", line 108, in close
    self._loop.call_soon(self._call_connection_lost, None)
  File "c:\users\zhong\appdata\local\programs\python\python38\lib\asyncio\base_events.py", line 711, in call_soon
    self._check_closed()
  File "c:\users\zhong\appdata\local\programs\python\python38\lib\asyncio\base_events.py", line 504, in _check_closed
    raise RuntimeError('Event loop is closed')
RuntimeError: Event loop is closed
Exception ignored in: <function _ProactorBasePipeTransport.__del__ at 0x000001FECD253670>
Traceback (most recent call last):
  File "c:\users\zhong\appdata\local\programs\python\python38\lib\asyncio\proactor_events.py", line 116, in __del__
    self.close()
  File "c:\users\zhong\appdata\local\programs\python\python38\lib\asyncio\proactor_events.py", line 108, in close
    self._loop.call_soon(self._call_connection_lost, None)
  File "c:\users\zhong\appdata\local\programs\python\python38\lib\asyncio\base_events.py", line 711, in call_soon
    self._check_closed()
  File "c:\users\zhong\appdata\local\programs\python\python38\lib\asyncio\base_events.py", line 504, in _check_closed
    raise RuntimeError('Event loop is closed')
RuntimeError: Event loop is closed
Exception ignored in: <function _ProactorBasePipeTransport.__del__ at 0x000001FECD253670>
Traceback (most recent call last):
  File "c:\users\zhong\appdata\local\programs\python\python38\lib\asyncio\proactor_events.py", line 116, in __del__
    self.close()
  File "c:\users\zhong\appdata\local\programs\python\python38\lib\asyncio\proactor_events.py", line 108, in close
    self._loop.call_soon(self._call_connection_lost, None)
  File "c:\users\zhong\appdata\local\programs\python\python38\lib\asyncio\base_events.py", line 711, in call_soon
    self._check_closed()
  File "c:\users\zhong\appdata\local\programs\python\python38\lib\asyncio\base_events.py", line 504, in _check_closed
    raise RuntimeError('Event loop is closed')
RuntimeError: Event loop is closed
Exception ignored in: <function _ProactorBasePipeTransport.__del__ at 0x000001FECD253670>
Traceback (most recent call last):
  File "c:\users\zhong\appdata\local\programs\python\python38\lib\asyncio\proactor_events.py", line 116, in __del__
    self.close()
  File "c:\users\zhong\appdata\local\programs\python\python38\lib\asyncio\proactor_events.py", line 108, in close
    self._loop.call_soon(self._call_connection_lost, None)
  File "c:\users\zhong\appdata\local\programs\python\python38\lib\asyncio\base_events.py", line 711, in call_soon
    self._check_closed()
  File "c:\users\zhong\appdata\local\programs\python\python38\lib\asyncio\base_events.py", line 504, in _check_closed
    raise RuntimeError('Event loop is closed')
RuntimeError: Event loop is closed
Exception ignored in: <function _ProactorBasePipeTransport.__del__ at 0x000001FECD253670>
Traceback (most recent call last):
  File "c:\users\zhong\appdata\local\programs\python\python38\lib\asyncio\proactor_events.py", line 116, in __del__
    self.close()
  File "c:\users\zhong\appdata\local\programs\python\python38\lib\asyncio\proactor_events.py", line 108, in close
    self._loop.call_soon(self._call_connection_lost, None)
  File "c:\users\zhong\appdata\local\programs\python\python38\lib\asyncio\base_events.py", line 711, in call_soon
    self._check_closed()
  File "c:\users\zhong\appdata\local\programs\python\python38\lib\asyncio\base_events.py", line 504, in _check_closed
    raise RuntimeError('Event loop is closed')
RuntimeError: Event loop is closed
Exception ignored in: <function _ProactorBasePipeTransport.__del__ at 0x000001FECD253670>
Traceback (most recent call last):
  File "c:\users\zhong\appdata\local\programs\python\python38\lib\asyncio\proactor_events.py", line 116, in __del__
    self.close()
  File "c:\users\zhong\appdata\local\programs\python\python38\lib\asyncio\proactor_events.py", line 108, in close
    self._loop.call_soon(self._call_connection_lost, None)
  File "c:\users\zhong\appdata\local\programs\python\python38\lib\asyncio\base_events.py", line 711, in call_soon
    self._check_closed()
  File "c:\users\zhong\appdata\local\programs\python\python38\lib\asyncio\base_events.py", line 504, in _check_closed
    raise RuntimeError('Event loop is closed')
RuntimeError: Event loop is closed
Exception ignored in: <function _ProactorBasePipeTransport.__del__ at 0x000001FECD253670>
Traceback (most recent call last):
  File "c:\users\zhong\appdata\local\programs\python\python38\lib\asyncio\proactor_events.py", line 116, in __del__
    self.close()
  File "c:\users\zhong\appdata\local\programs\python\python38\lib\asyncio\proactor_events.py", line 108, in close
    self._loop.call_soon(self._call_connection_lost, None)
  File "c:\users\zhong\appdata\local\programs\python\python38\lib\asyncio\base_events.py", line 711, in call_soon
    self._check_closed()
  File "c:\users\zhong\appdata\local\programs\python\python38\lib\asyncio\base_events.py", line 504, in _check_closed
    raise RuntimeError('Event loop is closed')
RuntimeError: Event loop is closed
Exception ignored in: <function _ProactorBasePipeTransport.__del__ at 0x000001FECD253670>
Traceback (most recent call last):
  File "c:\users\zhong\appdata\local\programs\python\python38\lib\asyncio\proactor_events.py", line 116, in __del__
    self.close()
  File "c:\users\zhong\appdata\local\programs\python\python38\lib\asyncio\proactor_events.py", line 108, in close
    self._loop.call_soon(self._call_connection_lost, None)
  File "c:\users\zhong\appdata\local\programs\python\python38\lib\asyncio\base_events.py", line 711, in call_soon
    self._check_closed()
  File "c:\users\zhong\appdata\local\programs\python\python38\lib\asyncio\base_events.py", line 504, in _check_closed
    raise RuntimeError('Event loop is closed')
RuntimeError: Event loop is closed
Exception ignored in: <function _ProactorBasePipeTransport.__del__ at 0x000001FECD253670>
Traceback (most recent call last):
  File "c:\users\zhong\appdata\local\programs\python\python38\lib\asyncio\proactor_events.py", line 116, in __del__
    self.close()
  File "c:\users\zhong\appdata\local\programs\python\python38\lib\asyncio\proactor_events.py", line 108, in close
    self._loop.call_soon(self._call_connection_lost, None)
  File "c:\users\zhong\appdata\local\programs\python\python38\lib\asyncio\base_events.py", line 711, in call_soon
    self._check_closed()
  File "c:\users\zhong\appdata\local\programs\python\python38\lib\asyncio\base_events.py", line 504, in _check_closed
    raise RuntimeError('Event loop is closed')
RuntimeError: Event loop is closed
Exception ignored in: <function _ProactorBasePipeTransport.__del__ at 0x000001FECD253670>
Traceback (most recent call last):
  File "c:\users\zhong\appdata\local\programs\python\python38\lib\asyncio\proactor_events.py", line 116, in __del__
    self.close()
  File "c:\users\zhong\appdata\local\programs\python\python38\lib\asyncio\proactor_events.py", line 108, in close
    self._loop.call_soon(self._call_connection_lost, None)
  File "c:\users\zhong\appdata\local\programs\python\python38\lib\asyncio\base_events.py", line 711, in call_soon
    self._check_closed()
  File "c:\users\zhong\appdata\local\programs\python\python38\lib\asyncio\base_events.py", line 504, in _check_closed
    raise RuntimeError('Event loop is closed')
RuntimeError: Event loop is closed
Exception ignored in: <function _ProactorBasePipeTransport.__del__ at 0x000001FECD253670>
Traceback (most recent call last):
  File "c:\users\zhong\appdata\local\programs\python\python38\lib\asyncio\proactor_events.py", line 116, in __del__
    self.close()
  File "c:\users\zhong\appdata\local\programs\python\python38\lib\asyncio\proactor_events.py", line 108, in close
    self._loop.call_soon(self._call_connection_lost, None)
  File "c:\users\zhong\appdata\local\programs\python\python38\lib\asyncio\base_events.py", line 711, in call_soon
    self._check_closed()
  File "c:\users\zhong\appdata\local\programs\python\python38\lib\asyncio\base_events.py", line 504, in _check_closed
    raise RuntimeError('Event loop is closed')
RuntimeError: Event loop is closed
Exception ignored in: <function _ProactorBasePipeTransport.__del__ at 0x000001FECD253670>
Traceback (most recent call last):
  File "c:\users\zhong\appdata\local\programs\python\python38\lib\asyncio\proactor_events.py", line 116, in __del__
    self.close()
  File "c:\users\zhong\appdata\local\programs\python\python38\lib\asyncio\proactor_events.py", line 108, in close
    self._loop.call_soon(self._call_connection_lost, None)
  File "c:\users\zhong\appdata\local\programs\python\python38\lib\asyncio\base_events.py", line 711, in call_soon
    self._check_closed()
  File "c:\users\zhong\appdata\local\programs\python\python38\lib\asyncio\base_events.py", line 504, in _check_closed
    raise RuntimeError('Event loop is closed')
RuntimeError: Event loop is closed
Exception ignored in: <function _ProactorBasePipeTransport.__del__ at 0x000001FECD253670>
Traceback (most recent call last):
  File "c:\users\zhong\appdata\local\programs\python\python38\lib\asyncio\proactor_events.py", line 116, in __del__
    self.close()
  File "c:\users\zhong\appdata\local\programs\python\python38\lib\asyncio\proactor_events.py", line 108, in close
    self._loop.call_soon(self._call_connection_lost, None)
  File "c:\users\zhong\appdata\local\programs\python\python38\lib\asyncio\base_events.py", line 711, in call_soon
    self._check_closed()
  File "c:\users\zhong\appdata\local\programs\python\python38\lib\asyncio\base_events.py", line 504, in _check_closed
    raise RuntimeError('Event loop is closed')
RuntimeError: Event loop is closed
Exception ignored in: <function _ProactorBasePipeTransport.__del__ at 0x000001FECD253670>
Traceback (most recent call last):
  File "c:\users\zhong\appdata\local\programs\python\python38\lib\asyncio\proactor_events.py", line 116, in __del__
    self.close()
  File "c:\users\zhong\appdata\local\programs\python\python38\lib\asyncio\proactor_events.py", line 108, in close
    self._loop.call_soon(self._call_connection_lost, None)
  File "c:\users\zhong\appdata\local\programs\python\python38\lib\asyncio\base_events.py", line 711, in call_soon
    self._check_closed()
  File "c:\users\zhong\appdata\local\programs\python\python38\lib\asyncio\base_events.py", line 504, in _check_closed
    raise RuntimeError('Event loop is closed')
RuntimeError: Event loop is closed
Exception ignored in: <function _ProactorBasePipeTransport.__del__ at 0x000001FECD253670>
Traceback (most recent call last):
  File "c:\users\zhong\appdata\local\programs\python\python38\lib\asyncio\proactor_events.py", line 116, in __del__
    self.close()
  File "c:\users\zhong\appdata\local\programs\python\python38\lib\asyncio\proactor_events.py", line 108, in close
    self._loop.call_soon(self._call_connection_lost, None)
  File "c:\users\zhong\appdata\local\programs\python\python38\lib\asyncio\base_events.py", line 711, in call_soon
    self._check_closed()
  File "c:\users\zhong\appdata\local\programs\python\python38\lib\asyncio\base_events.py", line 504, in _check_closed
    raise RuntimeError('Event loop is closed')
RuntimeError: Event loop is closed
Exception ignored in: <function _ProactorBasePipeTransport.__del__ at 0x000001FECD253670>
Traceback (most recent call last):
  File "c:\users\zhong\appdata\local\programs\python\python38\lib\asyncio\proactor_events.py", line 116, in __del__
    self.close()
  File "c:\users\zhong\appdata\local\programs\python\python38\lib\asyncio\proactor_events.py", line 108, in close
    self._loop.call_soon(self._call_connection_lost, None)
  File "c:\users\zhong\appdata\local\programs\python\python38\lib\asyncio\base_events.py", line 711, in call_soon
    self._check_closed()
  File "c:\users\zhong\appdata\local\programs\python\python38\lib\asyncio\base_events.py", line 504, in _check_closed
    raise RuntimeError('Event loop is closed')
RuntimeError: Event loop is closed
